<?xml version="1.0" ?>
<!-- =================================================================================== -->
<!-- |    This document was autogenerated by xacro from car.xacro                      | -->
<!-- |    EDITING THIS FILE BY HAND IS NOT RECOMMENDED                                 | -->
<!-- =================================================================================== -->
<robot name="6wd" xmlns:xacro="http://www.ros.org/wiki/xacro">
  <link name="base_link">
    <visual>
      <geometry>
        <mesh filename="package://car_description/meshes/body.dae"/>
      </geometry>
    </visual>
    <collision>
      <origin rpy="0 0 0" xyz="0 0 0.0256"/>
      <geometry>
        <box size="0.380 0.120 0.072"/>
      </geometry>
    </collision>
    <inertial>
      <mass value="3.3"/>
      <inertia ixx="0.005386" ixy="0.000000" ixz="0.00000" iyy="0.041136" iyz="0.00000" izz="0.04367"/>
    </inertial>
  </link>
  <link name="wheel_1_left">
    <visual>
      <geometry>
        <mesh filename="package://car_description/meshes/wheel_left.dae"/>
      </geometry>
    </visual>
    <collision>
      <origin rpy="1.5707 0 0" xyz="0 0.032 0"/>
      <geometry>
        <cylinder length="0.06" radius="0.063"/>
      </geometry>
    </collision>
    <inertial>
      <mass value="0.150"/>
      <inertia ixx="0.00019384" ixy="0.00000000" ixz="00000000" iyy="0.00019384" iyz="00000000" izz="0.004725"/>
    </inertial>
  </link>
  <joint name="wheel_1_left_joint" type="continuous">
    <parent link="base_link"/>
    <child link="wheel_1_left"/>
    <origin rpy="0 0 0" xyz="-0.15 0.083 0.001"/>
    <axis xyz="0 1 0"/>
  </joint>
  <link name="wheel_1_right">
    <visual>
      <geometry>
        <mesh filename="package://car_description/meshes/wheel_right.dae"/>
      </geometry>
    </visual>
    <collision>
      <origin rpy="1.5707 0 0" xyz="0 -0.032 0"/>
      <geometry>
        <cylinder length="0.06" radius="0.063"/>
      </geometry>
    </collision>
    <inertial>
      <mass value="0.150"/>
      <inertia ixx="0.00019384" ixy="0.00000000" ixz="00000000" iyy="0.00019384" iyz="00000000" izz="0.004725"/>
    </inertial>
  </link>
  <joint name="wheel_1_right_joint" type="continuous">
    <parent link="base_link"/>
    <child link="wheel_1_right"/>
    <origin rpy="0 0 0" xyz="-0.15 -0.083 0.001"/>
    <axis xyz="0 1 0"/>
  </joint>
  <link name="wheel_2_left">
    <visual>
      <geometry>
        <mesh filename="package://car_description/meshes/wheel_left.dae"/>
      </geometry>
    </visual>
    <collision>
      <origin rpy="1.5707 0 0" xyz="0 0.032 0"/>
      <geometry>
        <cylinder length="0.06" radius="0.063"/>
      </geometry>
    </collision>
    <inertial>
      <mass value="0.150"/>
      <inertia ixx="0.00019384" ixy="0.00000000" ixz="00000000" iyy="0.00019384" iyz="00000000" izz="0.004725"/>
    </inertial>
  </link>
  <joint name="wheel_2_left_joint" type="continuous">
    <parent link="base_link"/>
    <child link="wheel_2_left"/>
    <origin rpy="0 0 0" xyz="0 0.083 0"/>
    <axis xyz="0 1 0"/>
  </joint>
  <link name="wheel_2_right">
    <visual>
      <geometry>
        <mesh filename="package://car_description/meshes/wheel_right.dae"/>
      </geometry>
    </visual>
    <collision>
      <origin rpy="1.5707 0 0" xyz="0 -0.032 0"/>
      <geometry>
        <cylinder length="0.06" radius="0.063"/>
      </geometry>
    </collision>
    <inertial>
      <mass value="0.150"/>
      <inertia ixx="0.00019384" ixy="0.00000000" ixz="00000000" iyy="0.00019384" iyz="00000000" izz="0.004725"/>
    </inertial>
  </link>
  <joint name="wheel_2_right_joint" type="continuous">
    <parent link="base_link"/>
    <child link="wheel_2_right"/>
    <origin rpy="0 0 0" xyz="0 -0.083 0"/>
    <axis xyz="0 1 0"/>
  </joint>
  <link name="wheel_3_left">
    <visual>
      <geometry>
        <mesh filename="package://car_description/meshes/wheel_left.dae"/>
      </geometry>
    </visual>
    <collision>
      <origin rpy="1.5707 0 0" xyz="0 0.032 0"/>
      <geometry>
        <cylinder length="0.06" radius="0.063"/>
      </geometry>
    </collision>
    <inertial>
      <mass value="0.150"/>
      <inertia ixx="0.00019384" ixy="0.00000000" ixz="00000000" iyy="0.00019384" iyz="00000000" izz="0.004725"/>
    </inertial>
  </link>
  <joint name="wheel_3_left_joint" type="continuous">
    <parent link="base_link"/>
    <child link="wheel_3_left"/>
    <origin rpy="0 0 0" xyz="0.15 0.083 0.001"/>
    <axis xyz="0 1 0"/>
  </joint>
  <link name="wheel_3_right">
    <visual>
      <geometry>
        <mesh filename="package://car_description/meshes/wheel_right.dae"/>
      </geometry>
    </visual>
    <collision>
      <origin rpy="1.5707 0 0" xyz="0 -0.032 0"/>
      <geometry>
        <cylinder length="0.06" radius="0.063"/>
      </geometry>
    </collision>
    <inertial>
      <mass value="0.150"/>
      <inertia ixx="0.00019384" ixy="0.00000000" ixz="00000000" iyy="0.00019384" iyz="00000000" izz="0.004725"/>
    </inertial>
  </link>
  <joint name="wheel_3_right_joint" type="continuous">
    <parent link="base_link"/>
    <child link="wheel_3_right"/>
    <origin rpy="0 0 0" xyz="0.15 -0.083 0.001"/>
    <axis xyz="0 1 0"/>
  </joint>
  <link name="camera_link">
    <collision>
      <geometry>
        <box size="0.007 0.03 0.03"/>
      </geometry>
    </collision>
    <visual>
      <geometry>
        <mesh filename="package://car_description/meshes/camera.dae"/>
      </geometry>
      <material name="red"/>
    </visual>
    <inertial>
      <mass value="1e-5"/>
      <inertia ixx="1e-6" ixy="0" ixz="0" iyy="1e-6" iyz="0" izz="1e-6"/>
    </inertial>
  </link>
  <joint name="camera_joint" type="fixed">
    <axis xyz="0 0 0"/>
    <origin rpy="0 0 0" xyz="0.185 0 0.012"/>
    <parent link="base_link"/>
    <child link="camera_link"/>
  </joint>
  <gazebo reference="camera_link">
    <sensor name="camera1" type="camera">
      <update_rate>30.0</update_rate>
      <camera name="head">
        <horizontal_fov>1.08210413624</horizontal_fov>
        <image>
          <width>800</width>
          <height>800</height>
          <format>R8G8B8</format>
        </image>
        <clip>
          <near>0.02</near>
          <far>300</far>
        </clip>
        <noise>
          <type>gaussian</type>
          <mean>0.0</mean>
          <stddev>0.0</stddev>
        </noise>
        <distortion>
          <!-- radial -->
          <k1>0.0</k1>
          <k2>0.0</k2>
          <k3>0.0</k3>
          <!-- tangential -->
          <p1>-0.0</p1>
          <p2>-0.0</p2>
          <!-- distortion center (image center) -->
          <center>0.5 0.5</center>
        </distortion>
      </camera>
      <plugin filename="libgazebo_ros_camera.so" name="camera_controller">
        <alwaysOn>true</alwaysOn>
        <updateRate>30.0</updateRate>
        <cameraName>car_gazebo/camera1</cameraName>
        <imageTopicName>image_raw</imageTopicName>
        <cameraInfoTopicName>camera_info</cameraInfoTopicName>
        <frameName>camera_link</frameName>
        <hackBaseline>0.07</hackBaseline>
        <distortionK1>0.0</distortionK1>
        <distortionK2>0.0</distortionK2>
        <distortionK3>0.0</distortionK3>
        <distortionT1>0.0</distortionT1>
        <distortionT2>0.0</distortionT2>
      </plugin>
    </sensor>
  </gazebo>
  <gazebo>
    <plugin filename="libcar_plugin.so" name="car_plugin">
      <p>0.2</p>
      <i>0.0</i>
      <d>0.0</d>
      <max_velocity>17.0</max_velocity>
    </plugin>
  </gazebo>
</robot>

